Workbook

Sheet Cover
A1: MP Materials (MP) Key Metrics Summary | F1: Investment Thesis: MP Materials Corp (NYSE: MP)
A2: Done by: KOH ZEN YII | D2: Updated: 8 May 2026 | F2: 1. Strategic "10X" Vertical Integration
A3: COMPANY SUMMARY | D3: VALUE | F3: Asset Shift: Transitioning from a concentrate miner to a fully integrated magnet manufacturer.
A4: Company | D4: MP Materials Corp. | F4: The Texas Edge: The 10X facility in Fort Worth provides a massive margin expansion as the company captures the value-add of metallization and
A5: Ticker | D5: (NYSE: MP) | F5: magnet making, moving away from low-margin ore exports.
A6: Industry | D6: Rare Earth Materials
F7: 2. The $110/kg Price Floor Protection for NdPr
A8: Latest closing share price (USD) | D8: 69.13 | F8: The Strategic Revenue Protection Mechanism: Long-term offtake agreements and strategic reserve priorities establish a projected floor of $110/kg for NdPr.
A9: Latest closing share price date | D9: 46239 | F9: This advantage was granted to de-risk the massive capital investment required for the 10X facility, protecting the company from Chinese "predatory pricing"
A10: Latest fiscal year end date | D10: 31/12/2025 | F10: that historically bankrupts Western competitors. By stabilizing revenue at this level from 2025 to 2035, the U.S. ensures that MP Materials can survive
A11: Shares outstanding | D11: 178020000 | F11: market volatility to become a permanent, independent source of magnets for national security and the EV industry.
F13: 3. Capital Structure & Earnings Growth
A14: KEY METRICS | D14: VALUE | F14: Strategic Government Equity: In July 2025, the Department of Defense purchased $400 million in shares, establishing a 15% ownership stake. This direct
A15: Share Price ($/Share) | D15: ='DCF model'!G78 -> 28.204164 | F15: equity investment signals that the U.S. government is a long-term partner with a "vested interest" in the company's success.
A16: Downside | D16: =(D15-D8)/D8 -> -0.59201267 | F16: Targeted EBITDA Floor: The new 10X facility is expected to generate around $400M in annual EBITDA, supported by government-backed
A17: Shares Outstanding | D17: 178020000 | F17: agreements designed to secure a stable domestic supply of rare earth magnets for EVs and national security.
A18: Market Cap ($USD mil) | D18: 12282 | F18: Financial Advantage: The company is supported by $45M in direct government cash grants (DoD & Treasury) and $1.02B in total debt ,
A19: Total debt ( $USD mil) | D19: ='DCF model'!F29/1000 -> 1007.17 | F19: ensuring a strong liquidity position for the 10x facility expansion.
A20: Cash and Equivalents ($USD mil) | D20: ='DCF model'!G71/1000 -> 1830.286
A21: Enterprise Value ($USD mil) | D21: ='DCF model'!C66/1000 -> 4170.6793 | F21: 4. Geopolitical Arbitrage (2024/25 Compact)
F22: The Western Fortress: My research highlights MP's role in the U.S.-Australia Critical Minerals Compact. By pairing Australian separation (Lynas) with U.S.
F23: magnetics (MP),the partnership keeps the entire process in the U.S. so they don't have to rely on a single overseas source that could be cut off.
F24: Guaranteed Customers: Long-term supply agreements with General Motors (GM) and Apple solidify a guaranteed "Western-only" revenue stream.

Sheet DCF model
A1: Unlevered Free Cashflow
A3: All figures in USD thousands unless stated
A4: PROFIT METRICS | D4: =E4-1 -> 2025 | E4: 2026 | F4: =E4+1 -> 2027 | G4: =F4+1 -> 2028 | H4: =G4+1 -> 2029 | I4: =H4+1 -> 2030
A6: Revenue | D6: 275457 | E6: 565900 | F6: 991800 | G6: 1584500 | H6: 1857150 | I6: 2062000
A7: Rev. Growth | D7: 0.35 | E7: 1.05 | F7: 0.75 | G7: 0.6 | H7: 0.17 | I7: 0.11
A8: EBITDA Margin | D8: -0.22 | E8: 0.12 | F8: 0.28 | G8: 0.38 | H8: 0.44 | I8: 0.48
A9: EBITDA | D9: -60107 | E9: 66374 | F9: 272980 | G9: 596678 | H9: 808532 | I9: 986881
A11: D&A | D11: -89267 | E11: -122186 | F11: -120219 | G11: -127753 | H11: -138089 | I11: -130239
A12: Op. Profit (EBIT) | D12: =SUM(D9:D11) -> -149374 | E12: =SUM(E9:E11) -> -55812 | F12: =SUM(F9:F11) -> 152761 | G12: =SUM(G9:G11) -> 468925 | H12: =SUM(H9:H11) -> 670443 | I12: =SUM(I9:I11) -> 856642
A14: Tax Rate | D14: 0 | E14: 0 | F14: 0 | G14: 0.265 | H14: 0.265 | I14: 0.265
A15: Current Tax | D15: 0 | E15: 0 | F15: =F12*F14 -> 0 | G15: =G12*G14 -> 124265.12 | H15: =H12*H14 -> 177667.4 | I15: =I12*I14 -> 227010.13
A17: UNLEVERED FREE CASH FLOW
A19: EBITDA | D19: =D9 -> -60107 | E19: ='Forecast Calculation'!C21 -> 66373.5 | F19: ='Forecast Calculation'!D21 -> 272980 | G19: ='Forecast Calculation'!E21 -> 596678.2 | H19: ='Forecast Calculation'!F21 -> 808532.05 | I19: ='Forecast Calculation'!G21 -> 986880.98
A20: Current Taxes | D20: 0 | E20: 0 | F20: =F15 -> 0 | G20: =-G15 -> -124265.12 | H20: =-H15 -> -177667.4 | I20: =-I15 -> -227010.13
A21: Capital Expend. | D21: -172375 | E21: -150000 | F21: -400000 | G21: -500000 | H21: -200000 | I21: -55000
A22: Cash from NWC | D22: =-'Forecast Calculation'!C64 -> -23944 | E22: =-'Forecast Calculation'!D64 -> -10724.297 | F22: =-'Forecast Calculation'!E64 -> 24866.411 | G22: =-'Forecast Calculation'!F64 -> 92728.521 | H22: =-'Forecast Calculation'!G64 -> 25821.161 | I22: =-'Forecast Calculation'!H64 -> 7103.0541
A24: Unlevered FCF | D24: =SUM(D19:D22) -> -256426 | E24: =SUM(E19:E22) -> -94350.797 | F24: =SUM(F19:F22) -> -102153.59 | G24: =SUM(G19:G22) -> 65141.596 | H24: =SUM(H19:H22) -> 456685.81 | I24: =SUM(I19:I22) -> 711973.91
A27: WACC
A28: Equity Value | F28: 10836000
A29: Debt Value | F29: 1007170
A30: Cost of Debt | F30: =E41/F29 -> 0.031256888
A31: Tax Rate | F31: 0.265
A32: 10y Treasury | F32: 0.04248
A33: Beta | F33: 1.68
A34: Market Return | F34: 0.1
A35: Cost of Equity | F35: =F32+F33*(F34-F32) -> 0.1391136
A37: E/ D+E | F37: =F28/(F28+F29) -> 0.91495774
A38: D/ D+E | F38: =F29/(F29+F28) -> 0.085042265
A39: WACC | F39: =F37*F35+F38*F30*(1-F31) -> 0.12923681
A41: Interest Expense | E41: 31481
A44: Terminal Value
A45: Assumptions
A46: Growth Rate | D46: 0.02
B48: Period | D48: 0 | E48: 1 | F48: 2 | G48: 3 | H48: 4 | I48: 5
B49: FCF | D49: =D24 -> -256426 | E49: =E24 -> -94350.797 | F49: =F24 -> -102153.59 | G49: =G24 -> 65141.596 | H49: =H24 -> 456685.81 | I49: =I24 -> 711973.91
A53: * ( FCF from Y6 and onwards) | F53: Perpertuity Growth TV | I53: =I49*(1+D46)/(F39-D46) -> 6648064.8
A56: Enterprise Value
B58: Period | D58: 0 | E58: 1 | F58: 2 | G58: 3 | H58: 4 | I58: 5
A59: FCF | D59: =D24 -> -256426 | E59: =E49 -> -94350.797 | F59: =F49 -> -102153.59 | G59: =G49 -> 65141.596 | H59: =H49 -> 456685.81 | I59: =I49 -> 711973.91
A60: Terminal value | I60: =I53 -> 6648064.8
...

Sheet Forecast Calculation
A1: Revenue Forecast
A2: Metrics | B2: 2025A | C2: 2026F | D2: 2027F | E2: 2028F | F2: 2029F | G2: 2030F
A3: Refined NdPr Volume (in MT) [1] | B3: 1994000 | C3: 3690000 | D3: 5380000 | E3: 4950000 | F3: 4665000 | G3: 4200000
A4: Expected NdPr Price | B4: - | C4: 110 | D4: 110 | E4: 110 | F4: 110 | G4: 110
A5: NdPr Forecast Revenue | B5: - | C5: =(C3*C4)/1000 -> 405900 | D5: =(D3*D4)/1000 -> 591800 | E5: =(E3*E4)/1000 -> 544500 | F5: =(F3*F4)/1000 -> 513150 | G5: =(G3*G4)/1000 -> 462000
A6: Magnet Volume (kg) | B6: - | C6: 1000000 | D6: 2500000 | E6: 6500000 | F6: 8400000 | G6: 10000000
A7: Magnet Price | B7: - | C7: 160 | D7: 160 | E7: 160 | F7: 160 | G7: 160
A8: Magnet Sales | B8: - | C8: =(C6*C7)/1000 -> 160000 | D8: =(D6*D7)/1000 -> 400000 | E8: =(E6*E7)/1000 -> 1040000 | F8: =(F6*F7)/1000 -> 1344000 | G8: =(G6*G7)/1000 -> 1600000
A9: Total Revenue (including PPA) | B9: 275457 | C9: =(C5+C8)/1 -> 565900 | D9: =(D5+D8)/1 -> 991800 | E9: =(E5+E8)/1 -> 1584500 | F9: =(F5+F8)/1 -> 1857150 | G9: =(G5+G8)/1 -> 2062000
A10: Revenue Growth | B10: =(B9-203855)/203855 -> 0.35123985 | C10: =(C9-B9)/B9 -> 1.0544041 | D10: =(D9-C9)/C9 -> 0.75260647 | E10: =(E9-D9)/D9 -> 0.59760032 | F10: =(F9-E9)/E9 -> 0.17207321 | G10: =(G9-F9)/F9 -> 0.11030342
A11: Cost of Sales [2] | B11: 192789 | C11: =(C9*C12) -> 350858 | D11: =(D9*D12) -> 545490 | E11: =(E9*E12) -> 792250 | F11: =(F9*F12) -> 854289 | G11: =(G9*G12) -> 886660
A12: Cost of Sales (%) | B12: =B11/B9 -> 0.69988782 | C12: 0.62 | D12: 0.55 | E12: 0.5 | F12: 0.46 | G12: 0.43
A13: SG&A [3] | B13: 112066 | C13: =(C9*C14)/1 -> 121668.5 | D13: =(D9*D14)/1 -> 148770 | E13: =(E9*E14)/1 -> 158450 | F13: =(F9*F14)/1 -> 167143.5 | G13: =(G9*G14)/1 -> 173208
A14: SG&A (%) | B14: 0.407 | C14: 0.215 | D14: 0.15 | E14: 0.1 | F14: 0.09 | G14: 0.084
A15: Start-up [4] | B15: 4286 | C15: 15000 | D15: 10000 | E15: 20000 | F15: 15000 | G15: 5000
A16: Start-up (%) | B16: 0.016 | C16: =C15/C9 -> 0.02650645 | D16: =D15/D9 -> 0.010082678 | E16: =E15/E9 -> 0.012622278 | F16: =F15/F9 -> 0.008076892 | G16: =G15/G9 -> 0.0024248303
A17: Adv. projects [5] | B17: 24208 | C17: 10000 | D17: 12500 | E17: 15000 | F17: 10000 | G17: 8000
A18: Adv. projects (%) | B18: 8.8 | C18: =C17/C9 -> 0.017670967 | D18: =D17/D9 -> 0.012603347 | E18: =E17/E9 -> 0.0094667087 | F18: =F17/F9 -> 0.0053845947 | G18: =G17/G9 -> 0.0038797284
A19: Other operating expense | B19: 2215 | C19: 2000 | D19: =(C19*1.03)/1 -> 2060 | E19: =(D19*1.03) -> 2121.8 | F19: =(E19*1.03) -> 2185.454 | G19: =(F19*1.03) -> 2251.0176
A20: Other operating expense (%) | B20: =B19/B9 -> 0.0080411825 | C20: =C19/C9 -> 0.0035341933 | D20: =D19/D9 -> 0.0020770317 | E20: =E19/E9 -> 0.0013390975 | F20: =F19/F9 -> 0.0011767784 | G20: =G19/G9 -> 0.0010916671
A21: EBITDA | B21: =B9-B11-B13-B15-B17-B19 -> -60107 | C21: =C9-C11-C13-C15-C17-C19 -> 66373.5 | D21: =D9-D11-D13-D15-D17-D19 -> 272980 | E21: =E9-E11-E13-E15-E17-E19 -> 596678.2 | F21: =F9-F11-F13-F15-F17-F19 -> 808532.05 | G21: =G9-G11-G13-G15-G17-G19 -> 986880.98
A22: EBITDA margin (%) | B22: =B21/B9 -> -0.21820829 | C22: =C21/C9 -> 0.11728839 | D22: =D21/D9 -> 0.27523694 | E22: =E21/E9 -> 0.37657192 | F22: =F21/F9 -> 0.43536173 | G22: =G21/G9 -> 0.47860377
A24: Depreciation Forecast
A25: Depreciation Schedule | B25: 2025A | C25: 2026F | D25: 2027F | E25: 2028F | F25: 2029F | G25: 2030F
A26: Beginning PP&E | B26: =C26+B31-B27 -> 552212 | C26: 655000 | D26: =C26+C27-C31 -> 734841.17 | E26: =D26+D27-D31 -> 1064915.1 | F26: =E26+E27-E31 -> 1484559.6 | G26: =F26+F27-F31 -> 1589182.8
A27: (+) CapEx | B27: 172375 | C27: 150000 | D27: 400000 | E27: 500000 | F27: 200000 | G27: 55000
A28: Implied rate | B28: =B31/C26 -> 0.10623969 | C28: 0.10623969 | D28: 0.10623969 | E28: 0.10623969 | F28: 0.10623969 | G28: 0.10623969
A29: (-) Existing Assets Depreciation | B29: - | C29: =B26*B28 -> 58666.834 | D29: =(B26-SUM(C29)) *D28 -> 52434.088 | E29: =($B$26-SUM(C29:D29)) *E28 -> 46863.506 | F29: =($B$26-SUM(C29:E29)) *F28 -> 41884.742 | G29: =($B$26-SUM(C29:F29)) *G28 -> 37434.919
A30: (-) Total New Depreciation | B30: - | C30: ='Forecast Calculation'!C45 -> 11492 | D30: ='Forecast Calculation'!D45 -> 17492 | E30: ='Forecast Calculation'!E45 -> 33492 | F30: ='Forecast Calculation'!F45 -> 53492 | G30: ='Forecast Calculation'!G45 -> 61492
A31: (=) Total Depreciation | B31: 69587 | C31: =SUM(C29:C30) -> 70158.834 | D31: =SUM(D29:D30) -> 69926.088 | E31: =SUM(E29:E30) -> 80355.506 | F31: =SUM(F29:F30) -> 95376.742 | G31: =SUM(G29:G30) -> 98926.919
A32: REO Production (MT) | B32: 50692 | C32: 55000 | D32: 60000 | E32: 60000 | F32: 65000 | G32: 65000
A33: Rate per MT ($) | B33: 132.6 | C33: 132.6 | D33: 132.6 | E33: 132.6 | F33: 132.6 | G33: 132.6
A34: (= ) Total Depletion ($) | B34: 6724 | C34: =C32*C33/1000 -> 7293 | D34: =D32*D33/1000 -> 7956 | E34: =E32*E33/1000 -> 7956 | F34: =F32*F33/1000 -> 8619 | G34: =G32*G33/1000 -> 8619
A35: Amortization expense (intangibles) | B35: 1195 | C35: 1195 | D35: 1195 | E35: 1195 | F35: 1195 | G35: 1195
A36: Amortization expense (PPA) | B36: 11434 | C36: 43539 | D36: 41142 | E36: 38246 | F36: 32898 | G36: 21498
A37: Total DDA | B37: =SUM(B34:B36,B31) -> 88940 | C37: =SUM(C34:C36,C31) -> 122185.83 | D37: =SUM(D34:D36,D31) -> 120219.09 | E37: =SUM(E34:E36,E31) -> 127752.51 | F37: =SUM(F34:F36,F31) -> 138088.74 | G37: =SUM(G34:G36,G31) -> 130238.92
A39: Estimate Capex (10x facility) | B39: Annual Charge | C39: 2026F | D39: 2027F | E39: 2028F | F39: 2029F | G39: 2030F
A40: 2025 CapEx (172M) | B40: 172M /15 years | C40: 11492 | D40: 11492 | E40: 11492 | F40: 11492 | G40: 11492
A41: 2026 CapEx (150M) | B41: 150M/25 years | C41: 0 | D41: ='Forecast Calculation'!C27/25 -> 6000 | E41: 6000 | F41: 6000 | G41: 6000
A42: 2027 CapEx (400M) | B42: 400M/25 years | C42: 0 | D42: 0 | E42: 16000 | F42: ='Forecast Calculation'!D27/25 -> 16000 | G42: 16000
...

Sheet Assumptions
A1: Revenue Stream
A3: The projected NdPr consumptions for both magnet productions and external sales. [1]
A4: Year | B4: Total NdPr Produced (kg) | C4: Internal Consum. (to feed magnets) | D4: External Sales (The Leftover)
A5: 2026F | B5: 4000000 | C5: ~310,000 | D5: 3690000
A6: 2027F | B6: 6000000 | C6: ~620,000 | D6: 5380000
A7: 2028F | B7: 6500000 | C7: ~1,550,000 | D7: 4950000
A8: 2029F | B8: 7300000 | C8: ~2,635,000 | D8: 4665000
A9: 2030F | B9: 7300000 | C9: 3,100,000 (CAP) | D9: 4200000
A11: COST OF SALES FORECAST LOGIC [2]
A12: Logic: Mining/processing has HIGH fixed costs, LOW variable costs
A13: Fixed costs: ~$120M/yr (power, labor, equipment lease, D&D)
A14: Variable costs: ~$20-30/kg NdPr (reagents, consumables)
A15: 2025A: 70% — only 1,994 MT NdPr sold, fixed costs not covered
A16: 2026F: 62% — volume nearly doubles, fixed cost leverage kicks in
A17: 2027F: 55% — full NdPr ramp + magnets (higher margin product) in mix
A18: 2028F: 50% — magnets growing share of revenue, better unit economics
A19: 2029F: 46% — 10X scaling, further operating leverage
A20: 2030F: 43% — approaching mature integrated operation efficiency
A22: Why magnets improve CoS%:
A23: NdPr raw material is already "paid for" internally at cost
... A27: SGA FORECAST [3]
A28: Year | B28: SG&A (%) | C28: Justification
A29: 2025A | B29: 0.407 | C29: Elevated due to heavy hiring, management buildout, and pre-operational costs for 10X facility.
A30: 2026F | B30: 0.215 | C30: Revenue scales rapidly while SG&A grows modestly; operating leverage begins.
A31: 2027F | B31: 0.15 | C31: Continued revenue expansion (magnets ramp); SG&A grows slower than revenue.
A32: 2028F | B32: 0.1 | C32: Organizational structure largely built; incremental admin costs minimal.
A33: 2029F | B33: 0.09 | C33: Near steady-state operations; efficiency gains from scale.
A34: 2030F | B34: 0.084 | C34: Mature phase; SG&A stabilizes with inflation-level growth.
A36: START-UP COST FORECAST [4]
A37: Year | B37: Forecast ($) | C37: Justification (The "Why") | D37: Phase
A38: 2025A | B38: $4.3M | C38: Baseline: Minor costs associated with the final "Stage II" magnetic separation refinements. | D38: Late Construction
A39: 2026F | B39: $15.0M | C39: Independence Ramp: Significant spike as the Independence facility shifts to 24/7 magnet production. Includes hiring specialized metallurgists and initial "scrap" material waste. | D39: Hot Commissioning, 10-K form warned "may increase"
A40: 2027F | B40: $10.0M | C40: Stabilization: Independence becomes "commercial," moving these costs to COGS. Remaining $10M represents early site prep and hiring for 10X Texas. | D40: Early Prep
A41: 2028F | B41: $20.0M | C41: The 10X Peak: Massive spike for the $1.25B facility. This covers "Dry" and "Wet" testing, high utility surges to heat kilns, and training 1,500 new staff simultaneously. | D41: Peak Commissioning
A42: 2029F | B42: $15.0M | C42: Scaling Friction: Costs remain high but decline as the first production lines reach "spec." Focus shifts to calibrating the final expansion lines. | D42: Ramp-up
A43: 2030F | B43: $5.0M | C43: Steady State: Both plants are fully optimized. Start-up activities essentially cease, leaving only minor costs for new product R&D trials. | D43: Maturity
A45: ADV PROJECTS FORECAST [5]
A46: Year | B46: Advanced Projects ($K) | C46: Justification
A47: 2025A | B47: 4108 | C47: Normalized base (ex-deal costs)
A48: 2026F | B48: 10000 | C48: Pilots + early HREE/process work
...
